Workbook

Sheet Geral
C1: PREFEITURA MUNICIPAL DE CONTAGEM Secretaria Municipal de Desenvolvimento Social | G1: PLANO DE TRABALHO DO TERMO DE FOMENTO Nº 003/2019 – PROCESSO ADMINISTRATIVO Nº 019/2019/SMDS – EMENDA Nº 012/2019
A2: 1.1 SECRETARIA GESTORA DA POLÍTICA PÚBLICA
A3: Secretaria Municipal de Desenvolvimento Social
A4: Endereço | G4: Bairro
A5: Rua Portugal, nº 20 | G5: Glória
A6: Cidade | E6: U.F. | F6: CEP | H6: DDD/Fone
A7: Contagem | E7: MG | F7: 32.340-010 | H7: (031) 3392-1508
A8: 1.1.1 GESTOR (es) DA PARCERIA
A9: Bruno Eustáquio Pinheiro da Silva, matrícula 513734
A11: 1.2 OSC – ORGANIZAÇÃO DA SOCIEDADE CIVIL
A12: Nome | G12: CNPJ
A13: Associação dos Moradores do Bairro Novo Progresso II- AMONP | G13: 16.684.664/0001-57
A14: Endereço | G14: Bairro
A15: Rua Gonçalves Dias, 320 | G15: Novo Progresso
A16: Cidade | D16: U.F. | E16: CEP | G16: DDD/Fone
A17: Contagem | D17: MG | E17: 32140-610 | G17: 3362-3143
A18: Banco | D18: AGENCIA | E18: C.C | G18: e-mail:
A19: 104 | D19: 2940 | E19: 2465-2 | G19: financeiro@amnp.org
A20: 1.2.1 DIRIGENTE
A21: Nome do Responsável | G21: C.P.F
A22: Paulo Roberto da Silva | G22: 653.986.026-91
A23: R.G./Orgão Expedidor | E23: Cargo | G23: Período de Mandato
A24: MG-3.357.869 SSP/MG | E24: Presidente | G24: 18/02/2017 a 18/02/2021
A25: Endereço | G25: Bairro
A26: Rua 136, nº 490 | G26: Jardim Laguna
A27: Cidade | D27: U.F. | E27: CEP | G27: Telefone
A28: Contagem | D28: MG | E28: 32.140-000 | G28: 98637-0707
A29: Email
A30: amonp.institucional@gmail.com
A39: Paulo Roberto da Silva CPF: 653.986.026-91
A40: 2. DESCRIÇÃO DO OBJETO A SER EXECUTADO
A41: 2.1 DESCRIÇÃO DO OBJETO
A42: Título do Projeto | F42: Período de Execução
A43: Projeto Arte de Viver II | F43: Inicio | H43: Fim
F44: 43624 | H44: 43989
A45: Identificação do Objeto
A46: Execução do Projeto Social Arte de Viver II - que prevê o desenvolvimento de ações de convivência para crianças, adolescentes, idosos e respectivas famílias em situação de vulnerabilidade social .
A47: 3.JUSTIFICATIVA DA PROPOSIÇÃO
A48: O projeto proposto: Arte de Viver II organiza-se em grupos de modo a ampliar as trocas culturais e de vivências entre os usuários, assim como desenvolver o seu sentimento de pertença e de identidade. Como estratégia para prevenir situações de vulnerabilidade, violência e risco social o trabalho com grupos, a partir de faixas etárias e considerando as especificidades dos ciclos de vida, estimula as trocas culturais e o compartilhamento de vivências sempre sob a perspectiva de incentivar a socialização e a convivência familiar e comunitária. A proposta de Termo de Fomento apresentada propõe ações que buscam promover bons encontros, que fortaleçam a potência de agir impulsionando a ação para enfrentar situações conflituosas, alterar condições de subordinação, estabelecer diálogos, desejar e atuar por um mundo mais digno e mais justo. Enfim, promover mudanças em que haja corresponsabilidade entre a ação das políticas sociais e os sujeitos usuários.
A49: 4. ABRANGÊNCIA
...

Sheet PESSOAL CLT - 12 meses
A1: ANEXO I - DETALHAMENTO DA FORMAÇÃO DO CUSTO DE PESSOAL (CLT)
A2: DETALHAMENTO DE GASTO COM PESSOAL (12 meses)
A3: CARGO | B3: REMUNERAÇÃO | H3: ENCARGOS SOCIAIS E BENEFICIOS | U3: CUSTO TOTAL
B4: QTDE | C4: SALÁRIO | D4: 13º SALÁRIO | E4: Férias | F4: Férias - 1/3 | G4: Sub.Total REMUNERAÇÃO | H4: FGTS 8% | I4: Multa 50% FGTS | J4: INSS 20% Cota Patronal | K4: INSS 4,5% terceiros | L4: INSS 1% SAT | M4: PIS 1% | N4: Seguro de vida | O4: Plano odonto | P4: Plano de saúde | Q4: VT | R4: Uniforme | S4: Vale Alimentação (9,00 por dia) | T4: Total dos encargos
A5: Coordenadora de Cursos e Oficinas | B5: 1 | C5: 2200 | D5: =C5/12 -> 183.33333 | E5: =C5/12 -> 183.33333 | F5: =D5/3 -> 61.111111 | G5: =(SUM(C5:F5))*B5 -> 2627.7778 | H5: =C5*0.08 -> 176 | I5: =H5*0.5 -> 88 | N5: 0 | O5: 0 | P5: 0 | R5: 0 | S5: =9*20 -> 180 | T5: =(SUM(H5:S5))*B5 -> 444 | U5: =G5+T5 -> 3071.7778
A6: Auxiliar Administrativo | B6: 1 | C6: 1200 | D6: =C6/12 -> 100 | E6: =C6/12 -> 100 | F6: =D6/3 -> 33.333333 | G6: =(SUM(C6:F6))*B6 -> 1433.3333 | H6: =C6*0.08 -> 96 | I6: =H6*0.5 -> 48 | N6: 0 | O6: 0 | P6: 0 | R6: 0 | S6: =9*20 -> 180 | T6: =(SUM(H6:S6))*B6 -> 324 | U6: =G6+T6 -> 1757.3333
A7: Psicologa | B7: 1 | C7: 1700 | D7: =C7/12 -> 141.66667 | E7: =C7/12 -> 141.66667 | F7: =D7/3 -> 47.222222 | G7: =(SUM(C7:F7))*B7 -> 2030.5556 | H7: =C7*0.08 -> 136 | I7: =H7*0.5 -> 68 | K7: 0 | L7: 0 | N7: 0 | O7: 0 | P7: 0 | R7: 0 | S7: =9*20 -> 180 | T7: =(SUM(H7:S7))*B7 -> 384 | U7: =G7+T7 -> 2414.5556
A8: Recepcionista | B8: 2 | C8: 1100 | D8: =C8/12 -> 91.666667 | E8: =C8/12 -> 91.666667 | F8: =D8/3 -> 30.555556 | G8: =(SUM(C8:F8))*B8 -> 2627.7778 | H8: =C8*0.08 -> 88 | I8: =H8*0.5 -> 44 | K8: 0 | L8: 0 | N8: 0 | O8: 0 | P8: 0 | R8: 0 | S8: =9*20 -> 180 | T8: =(SUM(H8:S8))*B8 -> 624 | U8: =G8+T8 -> 3251.7778
A9: Analista de Projetos | B9: 1 | C9: 1850 | D9: =C9/12 -> 154.16667 | E9: =C9/12 -> 154.16667 | F9: =D9/3 -> 51.388889 | G9: =(SUM(C9:F9))*B9 -> 2209.7222 | H9: =C9*0.08 -> 148 | I9: =H9*0.5 -> 74 | K9: 0 | L9: 0 | N9: 0 | O9: 0 | P9: 0 | R9: 0 | S9: =9*20 -> 180 | T9: =(SUM(H9:S9))*B9 -> 402 | U9: =G9+T9 -> 2611.7222
A10: Serviços Gerais | B10: 2 | C10: 1040.55 | D10: =C10/12 -> 86.7125 | E10: =C10/12 -> 86.7125 | F10: =D10/3 -> 28.904167 | G10: =(SUM(C10:F10))*B10 -> 2485.7583 | H10: =C10*0.08 -> 83.244 | I10: =H10*0.5 -> 41.622 | K10: 0 | L10: 0 | N10: 0 | O10: 0 | P10: 0 | R10: 0 | S10: =9*20 -> 180 | T10: =(SUM(H10:S10))*B10 -> 609.732 | U10: =G10+T10 -> 3095.4903
A11: Educador Físico I | B11: 1 | C11: 1050 | D11: =C11/12 -> 87.5 | E11: =C11/12 -> 87.5 | F11: =D11/3 -> 29.166667 | G11: =(SUM(C11:F11))*B11 -> 1254.1667 | H11: =C11*0.08 -> 84 | I11: =H11*0.5 -> 42 | K11: 0 | L11: 0 | N11: 0 | O11: 0 | P11: 0 | R11: 0 | S11: =9*20 -> 180 | T11: =(SUM(H11:S11))*B11 -> 306 | U11: =G11+T11 -> 1560.1667
A12: Educador Físico II | B12: 1 | C12: 1200 | D12: =C12/12 -> 100 | E12: =C12/12 -> 100 | F12: =D12/3 -> 33.333333 | G12: =(SUM(C12:F12))*B12 -> 1433.3333 | H12: =C12*0.08 -> 96 | I12: =H12*0.5 -> 48 | K12: 0 | L12: 0 | N12: 0 | O12: 0 | P12: 0 | R12: 0 | S12: =9*20 -> 180 | T12: =(SUM(H12:S12))*B12 -> 324 | U12: =G12+T12 -> 1757.3333
A13: Educadora Social | B13: 1 | C13: 1400 | D13: =C13/12 -> 116.66667 | E13: =C13/12 -> 116.66667 | F13: =D13/3 -> 38.888889 | G13: =(SUM(C13:F13))*B13 -> 1672.2222 | H13: =C13*0.08 -> 112 | I13: =H13*0.5 -> 56 | K13: 0 | L13: 0 | N13: 0 | O13: 0 | P13: 0 | R13: 0 | S13: =9*20 -> 180 | T13: =(SUM(H13:S13))*B13 -> 348 | U13: =G13+T13 -> 2020.2222
A14: Educador Físico III | B14: 1 | C14: 1800 | D14: =C14/12 -> 150 | E14: =C14/12 -> 150 | F14: =D14/3 -> 50 | G14: =(SUM(C14:F14))*B14 -> 2150 | H14: =C14*0.08 -> 144 | I14: =H14*0.5 -> 72 | K14: 0 | L14: 0 | N14: 0 | O14: 0 | P14: 0 | R14: 0 | S14: =9*20 -> 180 | T14: =(SUM(H14:S14))*B14 -> 396 | U14: =G14+T14 -> 2546
A15: Coordenadora Administrativa | B15: 1 | C15: 4458.09 | D15: =C15/12 -> 371.5075 | E15: =C15/12 -> 371.5075 | F15: =D15/3 -> 123.83583 | G15: =(SUM(C15:F15))*B15 -> 5324.9408 | H15: =C15*0.08 -> 356.6472 | I15: =H15*0.5 -> 178.3236 | K15: 0 | L15: 0 | N15: 0 | O15: 0 | P15: 0 | R15: 0 | S15: =9*20 -> 180 | T15: =(SUM(H15:S15))*B15 -> 714.9708 | U15: =G15+T15 -> 6039.9116
A16: Analista Social | B16: 1 | C16: 3050.7 | D16: =C16/12 -> 254.225 | E16: =C16/12 -> 254.225 | F16: =D16/3 -> 84.741667 | G16: =(SUM(C16:F16))*B16 -> 3643.8917 | H16: =C16*0.08 -> 244.056 | I16: =H16*0.5 -> 122.028 | K16: 0 | L16: 0 | N16: 0 | O16: 0 | P16: 0 | R16: 0 | S16: =9*20 -> 180 | T16: =(SUM(H16:S16))*B16 -> 546.084 | U16: =G16+T16 -> 4189.9757
C17: 0 | D17: =C17/12 -> 0 | E17: =C17/12 -> 0 | F17: =D17/3 -> 0 | G17: =(SUM(C17:F17))*B17 -> 0 | H17: =C17*0.08 -> 0 | I17: =H17*0.5 -> 0 | K17: 0 | L17: 0 | N17: 0 | O17: 0 | P17: 0 | R17: 0 | T17: =(SUM(H17:S17))*B17 -> 0 | U17: =G17+T17 -> 0
C18: 0 | D18: =C18/12 -> 0 | E18: =C18/12 -> 0 | F18: =D18/3 -> 0 | G18: =(SUM(C18:F18))*B18 -> 0 | H18: =C18*0.08 -> 0 | I18: =H18*0.5 -> 0 | J18: =(G18*0.2) -> 0 | K18: 0 | L18: 0 | M18: =G18*0.01 -> 0 | N18: 0 | O18: 0 | P18: 0 | R18: 0 | T18: =(SUM(H18:S18))*B18 -> 0 | U18: =G18+T18 -> 0
C19: 0 | D19: =C19/12 -> 0 | E19: =C19/12 -> 0 | F19: =D19/3 -> 0 | G19: =(SUM(C19:F19))*B19 -> 0 | H19: =C19*0.08 -> 0 | I19: =H19*0.5 -> 0 | J19: =(G19*0.2) -> 0 | K19: 0 | L19: 0 | M19: =G19*0.01 -> 0 | N19: 0 | O19: 0 | P19: 0 | R19: 0 | T19: =(SUM(H19:S19))*B19 -> 0 | U19: =G19+T19 -> 0
C20: 0 | D20: =C20/12 -> 0 | E20: =C20/12 -> 0 | F20: =D20/3 -> 0 | G20: =(SUM(C20:F20))*B20 -> 0 | H20: =C20*0.08 -> 0 | I20: =H20*0.5 -> 0 | J20: =(G20*0.2) -> 0 | K20: 0 | L20: 0 | M20: =G20*0.01 -> 0 | N20: 0 | O20: 0 | P20: 0 | R20: 0 | T20: =(SUM(H20:S20))*B20 -> 0 | U20: =G20+T20 -> 0
C21: 0 | F21: =D21/3 -> 0 | G21: =(SUM(C21:F21))*B21 -> 0 | H21: =C21*0.08 -> 0 | I21: =H21*0.5 -> 0 | J21: =(G21*0.2) -> 0 | K21: 0 | L21: 0 | M21: =G21*0.01 -> 0 | N21: 0 | O21: 0 | P21: 0 | R21: 0 | T21: =(SUM(H21:S21))*B21 -> 0 | U21: =G21+T21 -> 0
C22: 0 | D22: =C22/12 -> 0 | E22: =C22/12 -> 0 | F22: =D22/3 -> 0 | G22: =(SUM(C22:F22))*B22 -> 0 | H22: =C22*0.08 -> 0 | I22: =H22*0.5 -> 0 | J22: =(G22*0.2) -> 0 | K22: 0 | L22: 0 | M22: =G22*0.01 -> 0 | N22: 0 | O22: 0 | P22: 0 | R22: 0 | T22: =(SUM(H22:S22))*B22 -> 0 | U22: =G22+T22 -> 0
C23: 0 | D23: =C23/12 -> 0 | E23: =C23/12 -> 0 | F23: =D23/3 -> 0 | G23: =(SUM(C23:F23))*B23 -> 0 | H23: =C23*0.08 -> 0 | I23: =H23*0.5 -> 0 | J23: =(G23*0.2) -> 0 | K23: 0 | L23: 0 | M23: =G23*0.01 -> 0 | N23: 0 | O23: 0 | P23: 0 | R23: 0 | T23: =(SUM(H23:S23))*B23 -> 0 | U23: =G23+T23 -> 0
A24: TOTAL MENSAL | B24: =SUM(B5:B23) -> 14 | C24: =SUM(C5:C23) -> 22049.34 | D24: =SUM(D5:D23) -> 1837.445 | E24: =SUM(E5:E23) -> 1837.445 | F24: =SUM(F5:F23) -> 612.48167 | G24: =SUM(G5:G23) -> 28893.48 | H24: =SUM(H5:H23) -> 1763.9472 | I24: =SUM(I5:I23) -> 881.9736 | ... R24: =SUM(R5:R23) -> 0 | T24: =SUM(T5:T23) -> 5422.7868 | U24: =SUM(U5:U23) -> 34316.267
A25: TOTAL EM 12 MESES | C25: =C24*12 -> 264592.08 | G25: =G24*12 -> 346721.76 | H25: =H24*12 -> 21167.366 | I25: =I24*12 -> 10583.683 | J25: =J24*12 -> 0 | M25: =M24*12 -> 0 | Q25: =Q24*12 -> 0 | T25: 65073.45 | U25: =U24*12 -> 411795.2
A28: NOTAS EXPLICATIVAS:
C29: QUANT | D29: SALÁRIO | E29: TOTAL
A30: Auxiliar Administrativo | C30: 3 | D30: 1300 | E30: =C30*D30 -> 3900
A31: Recepcionista | C31: 3 | D31: 1200 | E31: =C31*D31 -> 3600

Sheet CLT 10 meses
A1: ANEXO I - DETALHAMENTO DA FORMAÇÃO DO CUSTO DE PESSOAL (CLT)
A2: DETALHAMENTO DE GASTO COM PESSOAL (10 meses)
A3: CARGO | B3: REMUNERAÇÃO | H3: ENCARGOS SOCIAIS E BENEFICIOS | U3: CUSTO TOTAL
B4: QTDE | C4: SALÁRIO | D4: 13º SALÁRIO | E4: Férias | F4: Férias - 1/3 | G4: Sub.Total REMUNERAÇÃO | H4: FGTS 8% | I4: Multa 50% FGTS | J4: INSS 20% Cota Patronal | K4: INSS 4,5% terceiros | L4: INSS 1% SAT | M4: PIS 1% | N4: Seguro de vida | O4: Plano odonto | P4: Plano de saúde | Q4: VT | R4: Uniforme | S4: Vale Alimentação (9,00 por dia) | T4: Total dos encargos
A5: Serviços Gerais | B5: 1 | C5: 1040.55 | D5: =C5/12 -> 86.7125 | E5: =C5/12 -> 86.7125 | F5: =D5/3 -> 28.904167 | G5: =(SUM(C5:F5))*B5 -> 1242.8792 | H5: =C5*0.08 -> 83.244 | I5: =H5*0.5 -> 41.622 | K5: 0 | L5: 0 | N5: 0 | O5: 0 | P5: 0 | R5: 0 | S5: =9*20 -> 180 | T5: =(SUM(H5:S5))*B5 -> 304.866 | U5: =G5+T5 -> 1547.7452
A6: Orientador Social | B6: 1 | C6: 1050 | D6: =C6/12 -> 87.5 | E6: =C6/12 -> 87.5 | F6: =D6/3 -> 29.166667 | G6: =(SUM(C6:F6))*B6 -> 1254.1667 | H6: =C6*0.08 -> 84 | I6: =H6*0.5 -> 42 | K6: 0 | L6: 0 | N6: 0 | O6: 0 | P6: 0 | R6: 0 | S6: =9*20 -> 180 | T6: =(SUM(H6:S6))*B6 -> 306 | U6: =G6+T6 -> 1560.1667
A7: Auxiliar administrativo I | B7: 1 | C7: 1100 | D7: =C7/12 -> 91.666667 | E7: =C7/12 -> 91.666667 | F7: =D7/3 -> 30.555556 | G7: =(SUM(C7:F7))*B7 -> 1313.8889 | H7: =C7*0.08 -> 88 | I7: =H7*0.5 -> 44 | K7: 0 | L7: 0 | N7: 0 | O7: 0 | P7: 0 | R7: 0 | S7: =9*20 -> 180 | T7: =(SUM(H7:S7))*B7 -> 312 | U7: =G7+T7 -> 1625.8889
A8: Orientador Social | B8: 4 | C8: 2100 | D8: =C8/12 -> 175 | E8: =C8/12 -> 175 | F8: =D8/3 -> 58.333333 | G8: =(SUM(C8:F8))*B8 -> 10033.333 | H8: =C8*0.08 -> 168 | I8: =H8*0.5 -> 84 | K8: 0 | L8: 0 | N8: 0 | O8: 0 | P8: 0 | R8: 0 | S8: =9*20 -> 180 | T8: =(SUM(H8:S8))*B8 -> 1728 | U8: =G8+T8 -> 11761.333
A9: Assistente Administrativo | B9: 1 | C9: 2000 | D9: =C9/12 -> 166.66667 | E9: =C9/12 -> 166.66667 | F9: =D9/3 -> 55.555556 | G9: =(SUM(C9:F9))*B9 -> 2388.8889 | H9: =C9*0.08 -> 160 | I9: =H9*0.5 -> 80 | K9: 0 | L9: 0 | N9: 0 | O9: 0 | P9: 0 | R9: 0 | S9: =9*20 -> 180 | T9: =(SUM(H9:S9))*B9 -> 420 | U9: =G9+T9 -> 2808.8889
C10: 0 | D10: =C10/12 -> 0 | E10: =C10/12 -> 0 | F10: =D10/3 -> 0 | G10: =(SUM(C10:F10))*B10 -> 0 | H10: =C10*0.08 -> 0 | I10: =H10*0.5 -> 0 | J10: =(G10*0.2) -> 0 | K10: 0 | L10: 0 | N10: 0 | O10: 0 | P10: 0 | R10: 0 | T10: =(SUM(H10:S10))*B10 -> 0 | U10: =G10+T10 -> 0
C11: 0 | D11: =C11/12 -> 0 | E11: =C11/12 -> 0 | F11: =D11/3 -> 0 | G11: =(SUM(C11:F11))*B11 -> 0 | H11: =C11*0.08 -> 0 | I11: =H11*0.5 -> 0 | J11: =(G11*0.2) -> 0 | K11: 0 | L11: 0 | M11: =G11*0.01 -> 0 | N11: 0 | O11: 0 | P11: 0 | R11: 0 | T11: =(SUM(H11:S11))*B11 -> 0 | U11: =G11+T11 -> 0
C12: 0 | D12: =C12/12 -> 0 | E12: =C12/12 -> 0 | F12: =D12/3 -> 0 | G12: =(SUM(C12:F12))*B12 -> 0 | H12: =C12*0.08 -> 0 | I12: =H12*0.5 -> 0 | J12: =(G12*0.2) -> 0 | K12: 0 | L12: 0 | M12: =G12*0.01 -> 0 | N12: 0 | O12: 0 | P12: 0 | R12: 0 | T12: =(SUM(H12:S12))*B12 -> 0 | U12: =G12+T12 -> 0
C13: 0 | D13: =C13/12 -> 0 | E13: =C13/12 -> 0 | F13: =D13/3 -> 0 | G13: =(SUM(C13:F13))*B13 -> 0 | H13: =C13*0.08 -> 0 | I13: =H13*0.5 -> 0 | J13: =(G13*0.2) -> 0 | K13: 0 | L13: 0 | M13: =G13*0.01 -> 0 | N13: 0 | O13: 0 | P13: 0 | R13: 0 | T13: =(SUM(H13:S13))*B13 -> 0 | U13: =G13+T13 -> 0
C14: 0 | D14: =C14/12 -> 0 | E14: =C14/12 -> 0 | F14: =D14/3 -> 0 | G14: =(SUM(C14:F14))*B14 -> 0 | H14: =C14*0.08 -> 0 | I14: =H14*0.5 -> 0 | J14: =(G14*0.2) -> 0 | K14: 0 | L14: 0 | M14: =G14*0.01 -> 0 | N14: 0 | O14: 0 | P14: 0 | R14: 0 | T14: =(SUM(H14:S14))*B14 -> 0 | U14: =G14+T14 -> 0
C15: 0 | D15: =C15/12 -> 0 | E15: =C15/12 -> 0 | F15: =D15/3 -> 0 | G15: =(SUM(C15:F15))*B15 -> 0 | H15: =C15*0.08 -> 0 | I15: =H15*0.5 -> 0 | J15: =(G15*0.2) -> 0 | K15: 0 | L15: 0 | M15: =G15*0.01 -> 0 | N15: 0 | O15: 0 | P15: 0 | R15: 0 | T15: =(SUM(H15:S15))*B15 -> 0 | U15: =G15+T15 -> 0
C16: 0 | F16: =D16/3 -> 0 | G16: =(SUM(C16:F16))*B16 -> 0 | H16: =C16*0.08 -> 0 | I16: =H16*0.5 -> 0 | J16: =(G16*0.2) -> 0 | K16: 0 | L16: 0 | M16: =G16*0.01 -> 0 | N16: 0 | O16: 0 | P16: 0 | R16: 0 | T16: =(SUM(H16:S16))*B16 -> 0 | U16: =G16+T16 -> 0
C17: 0 | D17: =C17/12 -> 0 | E17: =C17/12 -> 0 | F17: =D17/3 -> 0 | G17: =(SUM(C17:F17))*B17 -> 0 | H17: =C17*0.08 -> 0 | I17: =H17*0.5 -> 0 | J17: =(G17*0.2) -> 0 | K17: 0 | L17: 0 | M17: =G17*0.01 -> 0 | N17: 0 | O17: 0 | P17: 0 | R17: 0 | T17: =(SUM(H17:S17))*B17 -> 0 | U17: =G17+T17 -> 0
C18: 0 | D18: =C18/12 -> 0 | E18: =C18/12 -> 0 | F18: =D18/3 -> 0 | G18: =(SUM(C18:F18))*B18 -> 0 | H18: =C18*0.08 -> 0 | I18: =H18*0.5 -> 0 | J18: =(G18*0.2) -> 0 | K18: 0 | L18: 0 | M18: =G18*0.01 -> 0 | N18: 0 | O18: 0 | P18: 0 | R18: 0 | T18: =(SUM(H18:S18))*B18 -> 0 | U18: =G18+T18 -> 0
A19: TOTAL MENSAL | B19: =SUM(B5:B18) -> 8 | C19: =SUM(C5:C18) -> 7290.55 | D19: =SUM(D5:D18) -> 607.54583 | E19: =SUM(E5:E18) -> 607.54583 | F19: =SUM(F5:F18) -> 202.51528 | G19: =SUM(G5:G18) -> 16233.157 | H19: =SUM(H5:H18) -> 583.244 | I19: =SUM(I5:I18) -> 291.622 | ... R19: =SUM(R5:R18) -> 0 | T19: =SUM(T5:T18) -> 3070.866 | U19: =SUM(U5:U18) -> 19304.023
A20: TOTAL EM 12 MESES | C20: =C19*10 -> 72905.5 | G20: =G19*10 -> 162331.57 | H20: =H19*10 -> 5832.44 | I20: =I19*10 -> 2916.22 | J20: =J19*12 -> 0 | M20: =M19*10 -> 0 | Q20: =Q19*12 -> 0 | T20: =T19*10 -> 30708.66 | U20: =U19*10 -> 193040.23
A23: NOTAS EXPLICATIVAS:
C24: QUANT | D24: SALÁRIO | E24: TOTAL
A25: Auxiliar Administrativo | C25: 3 | D25: 1300 | E25: =C25*D25 -> 3900
A26: Recepcionista | C26: 3 | D26: 1200 | E26: =C26*D26 -> 3600

Sheet SERVIÇOS DE TERCEIROS
A1: ANEXO II - DETALHAMENTO DA FORMAÇÃO DO CUSTO DE SERVIÇOS DE TERCEIROS
A2: DETALHAMENTO DE GASTO COM SERVIÇOS DE TERCEIROS
A3: N. | B3: Descrição | C3: Quantidade | D3: Valor Unitário | E3: Total Mensal | F3: QTDE DE MESES | G3: Total
A4: 1 | B4: Oficineiros | E4: 6857.71 | F4: 12 | G4: =E4*F4 -> 82292.52
A5: 2 | B5: Serviços contábeis | C5: 1 | D5: 2000 | E5: =D5*C5 -> 2000 | F5: 12 | G5: =E5*F5 -> 24000
A6: 3 | B6: Locação de Impressora | C6: 1 | D6: 180 | E6: =D6*C6 -> 180 | F6: 12 | G6: =E6*F6 -> 2160
A7: =1+A6 -> 4 | B7: Locação de Imóvel | C7: 1 | D7: 3000 | E7: =D7*C7 -> 3000 | F7: 12 | G7: =E7*F7 -> 36000
A8: =1+A7 -> 5 | B8: Locação de Imóvel | C8: 1 | D8: 3000 | E8: =D8*C8 -> 3000 | F8: 10 | G8: =E8*F8 -> 30000
A9: =1+A8 -> 6 | B9: Locação de Imóvel | C9: 1 | D9: 1300 | E9: =D9*C9 -> 1300 | F9: 10 | G9: =E9*F9 -> 13000
A10: =1+A9 -> 7 | B10: Locação de Imóvel | C10: 1 | D10: 800 | E10: =D10*C10 -> 800 | F10: 9 | G10: =E10*F10 -> 7200
A11: =1+A10 -> 8 | E11: =D11*C11 -> 0 | G11: =E11*F11 -> 0
A12: 9 | E12: =D12*C12 -> 0 | G12: =E12*F12 -> 0
A13: 10 | E13: =D13*C13 -> 0 | G13: =E13*F13 -> 0
A14: 11 | E14: =D14*C14 -> 0 | G14: =D14 -> 0
A15: 12 | E15: =D15*C15 -> 0 | G15: =C15*D15 -> 0
A16: =1+A15 -> 13 | E16: =D16*C16 -> 0 | G16: =C16*D16 -> 0
A17: =1+A16 -> 14
A18: 14
A19: 15
A20: 16
A21: Total dos Custos com Serviços de Terceiros | C21: - | D21: - | E21: =SUM(E1:E20) -> 17137.71 | F21: - | G21: =SUM(G4:G20) -> 194652.52
B22: NOTAS EXPLICATIVAS:
A23: 1 | B23: Contratação de prestadores de serviço por RPA/e ou MEI para ministrar oficinas diversas, de acordo com o planejamento da OSC .
A24: 2 | B24: Serviços contábeis (execução contábil da parceria e encerramento contábil)
A25: 3 | B25: Locação de Impressora para a execução do projeto.
A26: 4, 5, 6, 7 | B26: Locação de Imóveis (Regional Ressaca, Eldorado, Nacional e Vargem das Flores) para execução do projeto nas regionais.

Sheet M. Consumo
A1: ANEXO III - DETALHAMENTO DA FORMAÇÃO DO CUSTO DE MATERIAIS DE CONSUMO
A2: DETALHAMENTO DE GASTO COM MATERIAIS DE CONSUMO
A3: N. | B3: DESCRIÇÃO | C3: Valor Unitário | D3: Quantidade | E3: Total
A4: 1 | B4: Material de escritório / material gráfico e divulgação (banners, folders, revistas)/ premiações esportivas/ material esportivo(medalhas, troféus)/ material de proteção, segurança, socorro e sobrevivência/ fraldas descartáveis/ materiais elétricos, hidráulicos e de construção/ material de acondicionamento e embalagem/ material de higiene e limpeza/ descartáveis (copos, pratos, talheres, bandejas, guardanapos)/ material didático pedagógico e oficinas / suprimentos de informática / Vestuário/ Gás de cozinha P45. | C4: 500 | D4: 12 | E4: =C4*D4 -> 6000
A5: 2 | B5: Aquisição de lanches | C5: 100 | D5: 12 | E5: =C5*D5 -> 1200
A6: Custo Total com Materiais de Consumo | E6: =SUM(E4:E5) -> 7200
B7: NOTAS EXPLICATIVAS:
B8: Materiais de consumo para a execução do projeto no período de 12 meses.

Sheet C. Indiretos
A1: ANEXO IV - DETALHAMENTO DA FORMAÇÃO DOS CUSTO INDIRETOS
A2: DETALHAMENTO DE CUSTOS INDIRETOS
A3: N. | B3: Descrição | C3: Quantidade | D3: Média Mensal | E3: Total Anual
A4: 1 | B4: Serviços de Departamento Pessoal e Medicina do Trabalho | C4: 0 | D4: =NA() -> #N/A | E4: =D4*12 -> #N/A
A5: 1 | B5: Manutenção veículo / combustível / lubrificante / peças automotivas / seguro de veículo/ pneus/ Rastreadores de veículos. | C5: 12 | D5: 166.67 | E5: =D5*12 -> 2000.04
A6: 2 | B6: Água/ Luz / Telefone fixo e móvel/ Internet / Seguros | C6: 12 | D6: 1347.6 | E6: =D6*12 -> 16171.2
A7: 3 | B7: ASO - Admissional e Demissional | C7: 2 | D7: 1100 | E7: =D7*2 -> 2200
A8: 4 | E8: =D8*12 -> 0
A9: Total dos Custos Indiretos | D9: =SUM(D5:D8) -> 2614.27 | E9: =SUM(E5:E8) -> 20371.24
B10: NOTAS EXPLICATIVAS:
B11: Combustível e manutenção do veículo da OSC para acompanhar os projetos nas regionais

Sheet Investimentos
A1: ANEXO V - DETALHAMENTO DA FORMAÇÃO DOS INVESTIMENTOS
A2: DETALHAMENTO DOS MÓVEIS, MAQUINAS E EQUIPAMENTOS
A3: N. | B3: Descrição | C3: Quantidade | D3: Valor Unitário | E3: Total
A4: 1 | B4: Serviços de Departamento Pessoal e Medicina do Trabalho | C4: 0 | D4: 0 | E4: =C4*D4 -> 0
A5: 1 | E5: =C5*D5 -> 0
A6: 2 | E6: =C6*D6 -> 0
A7: 3 | E7: =C7*D7 -> 0
A8: 4 | E8: =C8*D8 -> 0
A9: 5 | E9: =C9*D9 -> 0
A10: 6 | E10: =C10*D10 -> 0
A11: 4 | E11: =C11*D11 -> 0
A12: 5 | E12: =C12*D12 -> 0
A13: 2 | E13: =C13*D13 -> 0
A14: 3 | E14: =C14*D14 -> 0
A15: 4 | E15: =C15*D15 -> 0
A16: 5 | E16: =C16*D16 -> 0
A17: Total dos Custos Com Investimentos | E17: =SUM(E4:E16) -> 0
B18: NOTAS EXPLICATIVAS:
